Workbook
Name in_active_power_mw_2026q2: Inputs!$B$2
Name in_mw_added_per_quarter: Inputs!$B$3
Name in_arr_per_new_mw_year_usd_m: Inputs!$B$4
Name in_revenue_to_midpoint_arr: Inputs!$B$5
Name in_ai_cloud_share_of_revenue: Inputs!$B$6
Name in_adjusted_ebitda_margin: Inputs!$B$7
Name in_capex_per_mw_usd_m: Inputs!$B$8
Name in_prepayment_share_of_capex: Inputs!$B$9
Name in_prepaid_revenue_recognised_share_per_quarter: Inputs!$B$10
Name in_other_operating_cash_share_of_capex: Inputs!$B$11
Name in_cost_of_debt: Inputs!$B$12
Name in_debt_share_of_capex: Inputs!$B$13
Name in_minimum_cash_usd_bn: Inputs!$B$14
Name in_disclosed_payback_months: Inputs!$B$15
Name in_arr_guidance_ye2026_low_usd_m: Inputs!$B$16
Name in_arr_guidance_ye2026_high_usd_m: Inputs!$B$17
Name in_revenue_guidance_2026_low_usd_m: Inputs!$B$18
Name in_revenue_guidance_2026_high_usd_m: Inputs!$B$19
Name in_mw_added_2026q3: Inputs!$B$20
Name in_mw_added_2026q4: Inputs!$B$21

Sheet README
A1: Nebius Group N.V. (NBIS) operating model
A2: Reported figures come from SEC EDGAR XBRL company facts; every assumption is on the Inputs sheet.
A4: as_of | B4: 2026-09-08
A5: cik | B5: 0001513845
A6: layer | B6: neocloud
A8: How to read this workbook
A9: This workbook is a snapshot of a Python model. The Inputs sheet holds every assumption the model takes as given (blue numbers): change one there and the formulas on the other sheets follow when Excel recalculates. Drivers are the operating quantities that build up by period; Outputs are what the model concludes from them. Each line shows its unit in column B; period columns ending in A are reported actuals, E are estimates. Click any formula cell to trace it back to the driver or input it depends on.
A11: Colour legend
A12: 1,234.5 | B12: Blue: a hard-coded input or assumption. Edit these on the Inputs sheet.
A13: =C5*C6 | B13: Black: a formula calculated from cells on the same sheet.
A14: =Drivers!C5 | B14: Green: a formula that links to another sheet (Inputs, Drivers or Outputs).
A15: 1,234.5 | B15: Grey: a value computed in Python and pasted (see the company module under companies/). It does not recalculate in Excel.
A17: Sheets
A18: Inputs | B18: One row per assumption: name, value, unit, source and note. Each value cell has the defined name in_<name> so formulas can refer to it by name.
A19: Drivers | B19: Operating drivers by period (label, unit, then one column per period).
A20: Outputs | B20: Model outputs by period, built from Drivers and Inputs.
A21: Disclosed | B21: Plain values exported from the model's 'disclosed' table.
A22: Reported | B22: Reported facts pulled from SEC XBRL company facts, one row per fact.
A23: Sensitivities | B23: Plain values exported from the model's 'sensitivities' table.
A25: Generated by ai-economics (https://github.com/Philbertcychan/ai-economics) via scripts/export_xlsx.py. Formulas recalculate when the file is opened in Excel.

Sheet Inputs
A1: Name | B1: Value | C1: Unit | D1: Source | E1: Note
A2: active_power_mw_2026q2 | B2: 300 | C2: MW | D2: 6-K EX-99.2 2026-02-12 (~170 MW active at Dec 31 2025; ARR 1.25 USD bn); 6-K EX-99.2 2026-08-12 (ARR 3.0 USD bn; 2026 base ACV 12 USD m per MW) | E2: [derived; proposed; range 250 to 400] Active power at June 30 2026 is not disclosed, so it is inferred from ARR. The fleet earned 7.4 USD m of ARR per active MW at Dec 31 2025 (1,250 / 170); the company shows its 2026 base contracts at about 12 USD m of annual contract value per MW. ARR of 3.0 USD bn at 10 USD m per MW, between the two, gives 300 MW. The forecast rolls forward from this number, so every per-MW line in the estimates depends on it; the range brackets the two rates.
A3: mw_added_per_quarter | B3: 200 | C3: MW | D3: 6-K EX-99.2 2026-05-13 and 2026-08-12 (800 MW to 1 GW connected by end 2026; more than 1 GW a year from 2027) | E3: [derived; proposed; range 150 to 300] Active power going live per quarter. The company expects 800 MW to 1 GW of CONNECTED power by December 2026 (built and equipped) and to deploy more than 1 GW a year from 2027. Active power lags connected power by GPU installation, so from 300 MW at June 2026, 200 MW a quarter reaches 700 MW active by December 2026 and 800 MW a year afterwards, a little under the 2027 deployment pace. Held flat.
A4: arr_per_new_mw_year_usd_m | B4: 14 | C4: USD m | D4: 6-K EX-99.2 2026-08-12 (Q2 deals above 20 USD m of annual contract value per MW; 2026 base 12 USD m; ARR guidance 7 to 9 USD bn at end 2026) | E4: [derived; proposed; range 10 to 22] Annualised revenue a newly live MW adds to ARR in the quarter it goes live. Contracts signed in Q2 2026 carry 20 to 25 USD m of annual contract value per MW, the 2026 base about 12, and a MW takes a quarter or two to fill. From 3.0 USD bn at June 2026 with 200 MW a quarter, 14 lands year-end 2026 ARR at 8.6 USD bn, inside the 7 to 9 USD bn guidance; 10 gives the bottom of the range and 17.5 the top.
A5: revenue_to_midpoint_arr | B5: 0.96 | C5: ratio | D5: 6-K EX-99.2 2026-02-12 to 2026-08-12 (AI cloud revenue and ARR) | E5: [derived; proposed; range 0.9 to 1] Quarterly AI cloud revenue as a share of one quarter of the average of opening and closing ARR: 0.95, 0.99 and 0.94 over the three quarters to June 2026 (Outputs sheet). Below 1 because ARR is the last month annualised and revenue grows through the quarter.
A6: ai_cloud_share_of_revenue | B6: 0.98 | C6: share | D6: 6-K EX-99.2 2026-02-12 to 2026-08-12 | E6: [derived; proposed; range 0.95 to 1] AI cloud revenue over group revenue: 0.94, 0.98 and 0.99 over the three quarters to June 2026. The other businesses (Avride, TripleTen) are small and growing slower, so the share drifts towards 1.
A7: adjusted_ebitda_margin | B7: 0.45 | C7: share | D7: 6-K EX-99.1 and EX-99.2 2026-02-12 to 2026-08-12 | E7: [derived; proposed; range 0.35 to 0.55] Group adjusted EBITDA margin was 6.6%, 32.5% and 40.6% over the three quarters to June 2026; the AI cloud segment reached 49.7% in Q2 2026 and the company guides to about 40% for 2026 as a whole. 45% from Q3 2026, held flat: the segment margin less the drag of the other businesses and of newly live capacity that has not filled.
A8: capex_per_mw_usd_m | B8: 25 | C8: USD m | D8: 6-K EX-99.1 2025-05-20 to 2026-08-12 (purchases of property and equipment); assumptions/CRWV.csv capex_per_mw_usd_m | E8: [derived; proposed; range 18 to 35] Capital expenditure per MW of active power added, applied in the quarter the MW goes live. Cumulative capex from Q1 2025 to Q2 2026 was 12,196 USD m against roughly 270 MW brought live (about 30 MW to the inferred 300), 45 per MW, but much of that spend is for capacity not yet live and for owned sites (New Jersey, Pennsylvania, Finland). CoreWeave's cumulative figure is 21.4 on leased sites with the same GPU generations. 25 allows for Nebius owning more of its data centres; a spend-to-live lag is not modelled.
A9: prepayment_share_of_capex | B9: 0.4 | C9: share | D9: 6-K EX-99.2 2026-08-12 (70% of deals include prepayments covering 50 to 60% of the associated capex; over 9 USD bn of prepayments expected in 2026) | E9: [derived; proposed; range 0.2 to 0.55] Customer prepayments received as a share of the quarter's capex. 70% of Q2 2026 deals carried prepayments covering 50 to 60% of their capex, 0.7 x 0.55 = 0.385. The 9 USD bn the company expects in 2026 against 4.4 USD bn of deferred revenue added in H1 leaves about 4.6 USD bn for H2, 46% of the model's H2 capex. Prepayments are cash before revenue; they sit in deferred revenue until the capacity is delivered.
A10: prepaid_revenue_recognised_share_per_quarter | B10: 0.06 | C10: share | E10: [judgment; proposed; range 0.03 to 0.12] Prepaid revenue recognised in a quarter as a share of the opening deferred-revenue balance (non-cash revenue). Not disclosed. Deferred revenue was 5,975 USD m at June 2026 against contracts that run three to five years and capacity that is still being built, so most of it has not started to unwind; 6% a quarter unwinds a balance over about four years. CoreWeave's measured share is 1% to 4%.
A11: other_operating_cash_share_of_capex | B11: -0.1 | C11: share | D11: 6-K EX-99.1 2025-05-20 to 2026-08-12 (cash flow statements) | E11: [derived; proposed; range -0.2 to 0] What cash from operations leaves unexplained after adjusted EBITDA and the change in deferred revenue: -1,344 USD m over the six quarters to June 2026 (Drivers sheet, other operating cash items). Receivables, supplier deposits and other assets that grow with the build-out, and interest paid. Expressed per dollar of capex (-11% over the period) rather than of revenue (-89%), because the items scale with the build, not with sales. In the forecast interest is shown separately, so this share carries the working capital only.
A12: cost_of_debt | B12: 0.02 | C12: decimal | D12: 6-K EX-99.1 2026-08-12 (balance sheet; proceeds from issuance of convertible notes) | E12: [judgment; proposed; range 0.01 to 0.05] Interest on the average debt balance. Debt of 8,546 USD m at June 2026 is almost entirely convertible notes issued in 2025 and Q1 2026, which carry low coupons; 2% is a round figure for the blend. Conventional GPU-backed debt, if added, would cost 7% to 10% (CoreWeave's stack).
A13: debt_share_of_capex | B13: 0.4 | C13: share | D13: 6-K EX-99.1 2025-11-12 to 2026-08-12 (cash flow statements) | E13: [derived; proposed; range 0.2 to 0.8] Net debt raised as a share of capex. Over the four quarters to June 2026 the company raised 8,500 USD m of convertible notes (76% of the 11,142 USD m of capex) and 6,000 USD m of equity and warrants, and now holds 8,042 USD m of cash. With prepayments covering 40% of capex the remaining need is smaller; 40% keeps net debt to EBITDA below 2x through 2028. Whatever the plan still lacks to hold minimum cash appears as external funding required, which is equity-like.
A14: minimum_cash_usd_bn | B14: 2 | C14: USD bn | E14: [judgment; proposed; range 1 to 4] Cash the company is assumed to keep on hand. Quarter-end cash was between 1.4 and 9.3 USD bn over the six quarters to June 2026. When the forecast cash balance would fall below this, the model shows the shortfall as external funding required: equity-like money that bears no interest and is not repaid, so it does not enter debt or leverage.
A15: disclosed_payback_months | B15: 22 | C15: months | D15: 6-K EX-99.2 2026-08-12 | E15: [disclosed; proposed] Not an input. The company's expected payback on the capex and related operating costs of the deals signed in Q2 2026: 1 year and 10 months, down from two to three years before. Shown beside the model's per-MW payback as a check; the company's figure is per deal, at the new contracts' 20 to 25 USD m of annual contract value per MW and net of their prepayments.
A16: arr_guidance_ye2026_low_usd_m | B16: 7000 | C16: USD m | D16: 6-K EX-99.2 2025-11-12; reaffirmed 2026-08-12 | E16: [disclosed; proposed] Not an input. The bottom of the company's 7 to 9 USD bn ARR guidance for the end of 2026, shown on the Outputs sheet against the model's ARR.
A17: arr_guidance_ye2026_high_usd_m | B17: 9000 | C17: USD m | D17: 6-K EX-99.2 2025-11-12; reaffirmed 2026-08-12 | E17: [disclosed; proposed] Not an input. The top of the same guidance.
A18: revenue_guidance_2026_low_usd_m | B18: 3000 | C18: USD m | D18: 6-K EX-99.2 2026-05-13; reaffirmed 2026-08-12 | E18: [disclosed; proposed] Not an input. The bottom of the company's 3.0 to 3.4 USD bn revenue guidance for 2026, shown on the Outputs sheet against the model's revenue. The model's straight-line ramp runs above it because the company's own ARR guidance implies most of the year's new capacity bills only in the fourth quarter.
A19: revenue_guidance_2026_high_usd_m | B19: 3400 | C19: USD m | D19: 6-K EX-99.2 2026-05-13; reaffirmed 2026-08-12 | E19: [disclosed; proposed] Not an input. The top of the same guidance.
A20: mw_added_2026q3 | B20: 50 | C20: MW | D20: 6-K EX-99.2 2026-05-13 and 2026-08-12 (2026 revenue guidance 3.0 to 3.4 USD bn; ARR guidance 7 to 9 USD bn; capacity added in Q3 to expand the footprint) | E20: [derived; proposed; range 25 to 200] Active power going live in Q3 2026, overriding the flat pace for this quarter. The company guides to 3.0 to 3.4 USD bn of 2026 revenue and 7 to 9 USD bn of ARR at year end. With 981 USD m booked in the first half, both hold only if little new capacity bills in Q3 and most of it arrives in Q4: 200 MW in each quarter gives 3.8 USD bn of revenue, above the range, while 50 then 350 gives 3.3 USD bn and the same 8.6 USD bn of ARR. The split is inferred from the guidance, not disclosed.
A21: mw_added_2026q4 | B21: 350 | C21: MW | D21: 6-K EX-99.2 2026-05-13 and 2026-08-12 (800 MW to 1 GW connected by end 2026) | E21: [derived; proposed; range 200 to 500] Active power going live in Q4 2026, overriding the flat pace for this quarter; see mw_added_2026q3. Takes active power from 350 MW to 700 MW at December 2026, inside the 800 MW to 1 GW of connected power the company expects by then.

Sheet Drivers
A1: Line item | B1: Unit | C1: 2025Q1A | D1: 2025Q2A | E1: 2025Q3A | F1: 2025Q4A | G1: 2026Q1A | H1: 2026Q2A | I1: 2026Q3E | J1: 2026Q4E | K1: 2027Q1E | L1: 2027Q2E | M1: 2027Q3E | N1: 2027Q4E | O1: 2028Q1E | P1: 2028Q2E | Q1: 2028Q3E | R1: 2028Q4E
A2: Active power going live, plan (register: mw_added_<quarter> where given, else mw_added_per_quarter) | B2: MW | I2: 50 | J2: 350 | K2: 200 | L2: 200 | M2: 200 | N2: 200 | O2: 200 | P2: 200 | Q2: 200 | R2: 200
A3: Active power, end of quarter (disclosed Dec 2025; June 2026 inferred from ARR) | B3: MW | F3: 170 | H3: 300 | I3: =H3+I2 | J3: =I3+J2 | K3: =J3+K2 | L3: =K3+L2 | M3: =L3+M2 | N3: =M3+N2 | O3: =N3+O2 | P3: =O3+P2 | ... R3: =Q3+R2
A4: Active power added (went live) | B4: MW | I4: =I3-H3 | J4: =J3-I3 | K4: =K3-J3 | L4: =L3-K3 | M4: =M3-L3 | N4: =N3-M3 | O4: =O3-N3 | P4: =P3-O3 | ... R4: =R3-Q3
A5: Active power, average | B5: MW | I5: =(H3+I3)/2 | J5: =(I3+J3)/2 | K5: =(J3+K3)/2 | L5: =(K3+L3)/2 | M5: =(L3+M3)/2 | N5: =(M3+N3)/2 | O5: =(N3+O3)/2 | P5: =(O3+P3)/2 | ... R5: =(Q3+R3)/2
A6: Annualised run-rate revenue (ARR), end of quarter | B6: USD m | C6: 249 | D6: 430 | E6: 551 | F6: 1250 | G6: 1900 | H6: 3000 | I6: =H6+I4*in_arr_per_new_mw_year_usd_m | J6: =I6+J4*in_arr_per_new_mw_year_usd_m | K6: =J6+K4*in_arr_per_new_mw_year_usd_m | L6: =K6+L4*in_arr_per_new_mw_year_usd_m | M6: =L6+M4*in_arr_per_new_mw_year_usd_m | N6: =M6+N4*in_arr_per_new_mw_year_usd_m | O6: =N6+O4*in_arr_per_new_mw_year_usd_m | P6: =O6+P4*in_arr_per_new_mw_year_usd_m | ... R6: =Q6+R4*in_arr_per_new_mw_year_usd_m
A7: AI cloud revenue | B7: USD m | F7: 214.2 | G7: 389.7 | H7: 574.9 | I7: =(H6+I6)/8*in_revenue_to_midpoint_arr | J7: =(I6+J6)/8*in_revenue_to_midpoint_arr | K7: =(J6+K6)/8*in_revenue_to_midpoint_arr | L7: =(K6+L6)/8*in_revenue_to_midpoint_arr | M7: =(L6+M6)/8*in_revenue_to_midpoint_arr | N7: =(M6+N6)/8*in_revenue_to_midpoint_arr | O7: =(N6+O6)/8*in_revenue_to_midpoint_arr | P7: =(O6+P6)/8*in_revenue_to_midpoint_arr | ... R7: =(Q6+R6)/8*in_revenue_to_midpoint_arr
A8: Revenue, group | B8: USD m | C8: 55.3 | D8: 105.1 | E8: 146.1 | F8: 227.7 | G8: 399 | H8: 582.3 | I8: =I7/in_ai_cloud_share_of_revenue | J8: =J7/in_ai_cloud_share_of_revenue | K8: =K7/in_ai_cloud_share_of_revenue | L8: =L7/in_ai_cloud_share_of_revenue | M8: =M7/in_ai_cloud_share_of_revenue | N8: =N7/in_ai_cloud_share_of_revenue | O8: =O7/in_ai_cloud_share_of_revenue | P8: =P7/in_ai_cloud_share_of_revenue | ... R8: =R7/in_ai_cloud_share_of_revenue
A9: Adjusted EBITDA, group | B9: USD m | C9: -62.6 | D9: -21 | E9: -5.2 | F9: 15 | G9: 129.5 | H9: 236.2 | I9: =I8*in_adjusted_ebitda_margin | J9: =J8*in_adjusted_ebitda_margin | K9: =K8*in_adjusted_ebitda_margin | L9: =L8*in_adjusted_ebitda_margin | M9: =M8*in_adjusted_ebitda_margin | N9: =N8*in_adjusted_ebitda_margin | O9: =O8*in_adjusted_ebitda_margin | P9: =P8*in_adjusted_ebitda_margin | ... R9: =R8*in_adjusted_ebitda_margin
A10: Capital expenditure | B10: USD m | C10: 543.9 | D10: 510.6 | E10: 955.5 | F10: 2056 | G10: 2472.9 | H10: 5657.4 | I10: =in_capex_per_mw_usd_m*I4 | J10: =in_capex_per_mw_usd_m*J4 | K10: =in_capex_per_mw_usd_m*K4 | L10: =in_capex_per_mw_usd_m*L4 | M10: =in_capex_per_mw_usd_m*M4 | N10: =in_capex_per_mw_usd_m*N4 | O10: =in_capex_per_mw_usd_m*O4 | P10: =in_capex_per_mw_usd_m*P4 | ... R10: =in_capex_per_mw_usd_m*R4
A11: Customer prepayments received | B11: USD m | I11: =I10*in_prepayment_share_of_capex | J11: =J10*in_prepayment_share_of_capex | K11: =K10*in_prepayment_share_of_capex | L11: =L10*in_prepayment_share_of_capex | M11: =M10*in_prepayment_share_of_capex | N11: =N10*in_prepayment_share_of_capex | O11: =O10*in_prepayment_share_of_capex | P11: =P10*in_prepayment_share_of_capex | ... R11: =R10*in_prepayment_share_of_capex
A12: Prepaid revenue recognised (non-cash) | B12: USD m | I12: =H15*in_prepaid_revenue_recognised_share_per_quarter | J12: =I15*in_prepaid_revenue_recognised_share_per_quarter | K12: =J15*in_prepaid_revenue_recognised_share_per_quarter | L12: =K15*in_prepaid_revenue_recognised_share_per_quarter | M12: =L15*in_prepaid_revenue_recognised_share_per_quarter | N12: =M15*in_prepaid_revenue_recognised_share_per_quarter | O12: =N15*in_prepaid_revenue_recognised_share_per_quarter | P12: =O15*in_prepaid_revenue_recognised_share_per_quarter | ... R12: =Q15*in_prepaid_revenue_recognised_share_per_quarter
A13: Change in deferred revenue (cash flow statement) | B13: USD m | C13: 2.5 | D13: 0.3 | E13: -3.8 | F13: 1566.5 | G13: 3198 | H13: 1197 | I13: =I11-I12 | J13: =J11-J12 | K13: =K11-K12 | L13: =L11-L12 | M13: =M11-M12 | N13: =N11-N12 | O13: =O11-O12 | P13: =P11-P12 | ... R13: =R11-R12
A14: Other deferred revenue movements (plug to reported balance) | B14: USD m | C14: 0 | D14: 0 | E14: 0.1 | F14: -4.6 | G14: 2.6 | H14: 0.1 | I14: 0 | J14: 0 | K14: 0 | L14: 0 | M14: 0 | N14: 0 | O14: 0 | P14: 0 | Q14: 0 | R14: 0
A15: Deferred revenue, end of quarter | B15: USD m | C15: 19 | D15: 19.3 | E15: 15.6 | F15: 1577.5 | G15: 4778.1 | H15: 5975.2 | I15: =H15+I13+I14 | J15: =I15+J13+J14 | K15: =J15+K13+K14 | L15: =K15+L13+L14 | M15: =L15+M13+M14 | N15: =M15+N13+N14 | O15: =N15+O13+O14 | P15: =O15+P13+P14 | ... R15: =Q15+R13+R14
A16: Interest on debt (inside other items in actuals) | B16: USD m | I16: =(H20+I20)/2*in_cost_of_debt/4 | J16: =(I20+J20)/2*in_cost_of_debt/4 | K16: =(J20+K20)/2*in_cost_of_debt/4 | L16: =(K20+L20)/2*in_cost_of_debt/4 | M16: =(L20+M20)/2*in_cost_of_debt/4 | N16: =(M20+N20)/2*in_cost_of_debt/4 | O16: =(N20+O20)/2*in_cost_of_debt/4 | P16: =(O20+P20)/2*in_cost_of_debt/4 | ... R16: =(Q20+R20)/2*in_cost_of_debt/4
A17: Other operating cash items (actuals: everything between EBITDA plus deferred revenue and reported cash from operations) | B17: USD m | C17: -124 | D17: -147.2 | E17: -71.6 | F17: -747.2 | G17: -1069.5 | H17: 812.9 | I17: =I10*in_other_operating_cash_share_of_capex | J17: =J10*in_other_operating_cash_share_of_capex | K17: =K10*in_other_operating_cash_share_of_capex | L17: =L10*in_other_operating_cash_share_of_capex | M17: =M10*in_other_operating_cash_share_of_capex | N17: =N10*in_other_operating_cash_share_of_capex | O17: =O10*in_other_operating_cash_share_of_capex | P17: =P10*in_other_operating_cash_share_of_capex | ... R17: =R10*in_other_operating_cash_share_of_capex
A18: Cash from operations | B18: USD m | C18: -184.1 | D18: -167.9 | E18: -80.6 | F18: 834.3 | G18: 2258 | H18: 2246.1 | I18: =I9-I16+I13+I17 | J18: =J9-J16+J13+J17 | K18: =K9-K16+K13+K17 | L18: =L9-L16+L13+L17 | M18: =M9-M16+M13+M17 | N18: =N9-N16+N13+N17 | O18: =O9-O16+O13+O17 | P18: =P9-P16+P13+P17 | ... R18: =R9-R16+R13+R17
A19: Debt raised, net (actuals: change in the reported balance) | B19: USD m | C19: 0.1 | D19: 980 | E19: 3120.6 | F19: 20.9 | G19: 4322.7 | H19: 95.3 | I19: =I10*in_debt_share_of_capex | J19: =J10*in_debt_share_of_capex | K19: =K10*in_debt_share_of_capex | L19: =L10*in_debt_share_of_capex | M19: =M10*in_debt_share_of_capex | N19: =N10*in_debt_share_of_capex | O19: =O10*in_debt_share_of_capex | P19: =P10*in_debt_share_of_capex | ... R19: =R10*in_debt_share_of_capex
A20: Debt, end of quarter | B20: USD m | C20: 6.2 | D20: 986.2 | E20: 4106.8 | F20: 4127.7 | G20: 8450.4 | H20: 8545.7 | I20: =H20+I19 | J20: =I20+J19 | K20: =J20+K19 | L20: =K20+L19 | M20: =L20+M19 | N20: =M20+N19 | O20: =N20+O19 | P20: =O20+P19 | ... R20: =Q20+R19
A21: Equity raised and other investing and financing (plug to reported cash) | B21: USD m | C21: -274.7 | D21: -69.2 | E21: 1031 | F21: 84.1 | G21: 1512.3 | H21: 2059.9 | I21: 0 | J21: 0 | K21: 0 | L21: 0 | M21: 0 | N21: 0 | O21: 0 | P21: 0 | Q21: 0 | R21: 0
A22: External funding required to hold minimum cash (equity-like, no interest) | B22: USD m | C22: 0 | D22: 0 | E22: 0 | F22: 0 | G22: 0 | H22: 0 | I22: =MAX(0,in_minimum_cash_usd_bn*1000-(H23+I18-I10+I19+I21)) | J22: =MAX(0,in_minimum_cash_usd_bn*1000-(I23+J18-J10+J19+J21)) | K22: =MAX(0,in_minimum_cash_usd_bn*1000-(J23+K18-K10+K19+K21)) | L22: =MAX(0,in_minimum_cash_usd_bn*1000-(K23+L18-L10+L19+L21)) | M22: =MAX(0,in_minimum_cash_usd_bn*1000-(L23+M18-M10+M19+M21)) | N22: =MAX(0,in_minimum_cash_usd_bn*1000-(M23+N18-N10+N19+N21)) | O22: =MAX(0,in_minimum_cash_usd_bn*1000-(N23+O18-O10+O19+O21)) | P22: =MAX(0,in_minimum_cash_usd_bn*1000-(O23+P18-P10+P19+P21)) | ... R22: =MAX(0,in_minimum_cash_usd_bn*1000-(Q23+R18-R10+R19+R21))
A23: Cash and cash equivalents, end of quarter | B23: USD m | C23: 1447 | D23: 1679.3 | E23: 4794.8 | F23: 3678.1 | G23: 9298.2 | H23: 8042.1 | I23: =H23+I18-I10+I19+I21+I22 | J23: =I23+J18-J10+J19+J21+J22 | K23: =J23+K18-K10+K19+K21+K22 | L23: =K23+L18-L10+L19+L21+L22 | M23: =L23+M18-M10+M19+M21+M22 | N23: =M23+N18-N10+N19+N21+N22 | O23: =N23+O18-O10+O19+O21+O22 | P23: =O23+P18-P10+P19+P21+P22 | ... R23: =Q23+R18-R10+R19+R21+R22

Sheet Outputs
A1: Line item | B1: Unit | C1: 2025Q1A | D1: 2025Q2A | E1: 2025Q3A | F1: 2025Q4A | G1: 2026Q1A | H1: 2026Q2A | I1: 2026Q3E | J1: 2026Q4E | K1: 2027Q1E | L1: 2027Q2E | M1: 2027Q3E | N1: 2027Q4E | O1: 2028Q1E | P1: 2028Q2E | Q1: 2028Q3E | R1: 2028Q4E
A2: Revenue growth, quarter on quarter | B2: % | C2: 3.8508772 | D2: =Drivers!D8/Drivers!C8-1 | E2: =Drivers!E8/Drivers!D8-1 | F2: =Drivers!F8/Drivers!E8-1 | G2: =Drivers!G8/Drivers!F8-1 | H2: =Drivers!H8/Drivers!G8-1 | I2: =Drivers!I8/Drivers!H8-1 | J2: =Drivers!J8/Drivers!I8-1 | K2: =Drivers!K8/Drivers!J8-1 | ... R2: =Drivers!R8/Drivers!Q8-1
A3: Adjusted EBITDA margin | B3: % | C3: =Drivers!C9/Drivers!C8 | D3: =Drivers!D9/Drivers!D8 | E3: =Drivers!E9/Drivers!E8 | F3: =Drivers!F9/Drivers!F8 | G3: =Drivers!G9/Drivers!G8 | H3: =Drivers!H9/Drivers!H8 | I3: =Drivers!I9/Drivers!I8 | J3: =Drivers!J9/Drivers!J8 | ... R3: =Drivers!R9/Drivers!R8
A4: AI cloud share of group revenue | B4: % | C4: =Drivers!C7/Drivers!C8 | D4: =Drivers!D7/Drivers!D8 | E4: =Drivers!E7/Drivers!E8 | F4: =Drivers!F7/Drivers!F8 | G4: =Drivers!G7/Drivers!G8 | H4: =Drivers!H7/Drivers!H8 | I4: =Drivers!I7/Drivers!I8 | J4: =Drivers!J7/Drivers!J8 | ... R4: =Drivers!R7/Drivers!R8
A5: AI cloud revenue / one quarter of average ARR (calibration) | B5: ratio | D5: =Drivers!D7/((Drivers!C6+Drivers!D6)/8) | E5: =Drivers!E7/((Drivers!D6+Drivers!E6)/8) | F5: =Drivers!F7/((Drivers!E6+Drivers!F6)/8) | G5: =Drivers!G7/((Drivers!F6+Drivers!G6)/8) | H5: =Drivers!H7/((Drivers!G6+Drivers!H6)/8) | I5: =Drivers!I7/((Drivers!H6+Drivers!I6)/8) | J5: =Drivers!J7/((Drivers!I6+Drivers!J6)/8) | K5: =Drivers!K7/((Drivers!J6+Drivers!K6)/8) | ... R5: =Drivers!R7/((Drivers!Q6+Drivers!R6)/8)
A6: ARR per active MW, fleet average | B6: USD m | C6: =Drivers!C6/Drivers!C3 | D6: =Drivers!D6/Drivers!D3 | E6: =Drivers!E6/Drivers!E3 | F6: =Drivers!F6/Drivers!F3 | G6: =Drivers!G6/Drivers!G3 | H6: =Drivers!H6/Drivers!H3 | I6: =Drivers!I6/Drivers!I3 | J6: =Drivers!J6/Drivers!J3 | ... R6: =Drivers!R6/Drivers!R3
A7: ARR guidance for end 2026, low | B7: USD m | C7: =in_arr_guidance_ye2026_low_usd_m | D7: =in_arr_guidance_ye2026_low_usd_m | E7: =in_arr_guidance_ye2026_low_usd_m | F7: =in_arr_guidance_ye2026_low_usd_m | G7: =in_arr_guidance_ye2026_low_usd_m | H7: =in_arr_guidance_ye2026_low_usd_m | I7: =in_arr_guidance_ye2026_low_usd_m | J7: =in_arr_guidance_ye2026_low_usd_m | ... R7: =in_arr_guidance_ye2026_low_usd_m
A8: ARR guidance for end 2026, high | B8: USD m | C8: =in_arr_guidance_ye2026_high_usd_m | D8: =in_arr_guidance_ye2026_high_usd_m | E8: =in_arr_guidance_ye2026_high_usd_m | F8: =in_arr_guidance_ye2026_high_usd_m | G8: =in_arr_guidance_ye2026_high_usd_m | H8: =in_arr_guidance_ye2026_high_usd_m | I8: =in_arr_guidance_ye2026_high_usd_m | J8: =in_arr_guidance_ye2026_high_usd_m | ... R8: =in_arr_guidance_ye2026_high_usd_m
A9: Revenue guidance for 2026, low (full year) | B9: USD m | C9: =in_revenue_guidance_2026_low_usd_m | D9: =in_revenue_guidance_2026_low_usd_m | E9: =in_revenue_guidance_2026_low_usd_m | F9: =in_revenue_guidance_2026_low_usd_m | G9: =in_revenue_guidance_2026_low_usd_m | H9: =in_revenue_guidance_2026_low_usd_m | I9: =in_revenue_guidance_2026_low_usd_m | J9: =in_revenue_guidance_2026_low_usd_m | ... R9: =in_revenue_guidance_2026_low_usd_m
A10: Revenue guidance for 2026, high (full year) | B10: USD m | C10: =in_revenue_guidance_2026_high_usd_m | D10: =in_revenue_guidance_2026_high_usd_m | E10: =in_revenue_guidance_2026_high_usd_m | F10: =in_revenue_guidance_2026_high_usd_m | G10: =in_revenue_guidance_2026_high_usd_m | H10: =in_revenue_guidance_2026_high_usd_m | I10: =in_revenue_guidance_2026_high_usd_m | J10: =in_revenue_guidance_2026_high_usd_m | ... R10: =in_revenue_guidance_2026_high_usd_m
A11: Adjusted EBITDA per average active MW, annualised | B11: USD m | I11: =Drivers!I9*4/Drivers!I5 | J11: =Drivers!J9*4/Drivers!J5 | K11: =Drivers!K9*4/Drivers!K5 | L11: =Drivers!L9*4/Drivers!L5 | M11: =Drivers!M9*4/Drivers!M5 | N11: =Drivers!N9*4/Drivers!N5 | O11: =Drivers!O9*4/Drivers!O5 | P11: =Drivers!P9*4/Drivers!P5 | ... R11: =Drivers!R9*4/Drivers!R5
A12: Payback per new MW: capex per MW / EBITDA per MW | B12: years | I12: =in_capex_per_mw_usd_m/I11 | J12: =in_capex_per_mw_usd_m/J11 | K12: =in_capex_per_mw_usd_m/K11 | L12: =in_capex_per_mw_usd_m/L11 | M12: =in_capex_per_mw_usd_m/M11 | N12: =in_capex_per_mw_usd_m/N11 | O12: =in_capex_per_mw_usd_m/O11 | P12: =in_capex_per_mw_usd_m/P11 | ... R12: =in_capex_per_mw_usd_m/R11
A13: Payback per new MW, net of the customer prepayment | B13: years | I13: =in_capex_per_mw_usd_m*(1-in_prepayment_share_of_capex)/I11 | J13: =in_capex_per_mw_usd_m*(1-in_prepayment_share_of_capex)/J11 | K13: =in_capex_per_mw_usd_m*(1-in_prepayment_share_of_capex)/K11 | L13: =in_capex_per_mw_usd_m*(1-in_prepayment_share_of_capex)/L11 | M13: =in_capex_per_mw_usd_m*(1-in_prepayment_share_of_capex)/M11 | N13: =in_capex_per_mw_usd_m*(1-in_prepayment_share_of_capex)/N11 | O13: =in_capex_per_mw_usd_m*(1-in_prepayment_share_of_capex)/O11 | P13: =in_capex_per_mw_usd_m*(1-in_prepayment_share_of_capex)/P11 | ... R13: =in_capex_per_mw_usd_m*(1-in_prepayment_share_of_capex)/R11
A14: Payback, as disclosed by the company (Q2 2026 deals) | B14: years | C14: =in_disclosed_payback_months/12 | D14: =in_disclosed_payback_months/12 | E14: =in_disclosed_payback_months/12 | F14: =in_disclosed_payback_months/12 | G14: =in_disclosed_payback_months/12 | H14: =in_disclosed_payback_months/12 | I14: =in_disclosed_payback_months/12 | J14: =in_disclosed_payback_months/12 | ... R14: =in_disclosed_payback_months/12
A15: Prepayments / capex (actuals: change in deferred revenue / capex) | B15: % | C15: 0.0045964332 | D15: 0.00058754407 | E15: -0.0039769754 | F15: 0.76191634 | G15: 1.2932185 | H15: 0.21158129 | I15: =Drivers!I11/Drivers!I10 | J15: =Drivers!J11/Drivers!J10 | K15: =Drivers!K11/Drivers!K10 | L15: =Drivers!L11/Drivers!L10 | M15: =Drivers!M11/Drivers!M10 | N15: =Drivers!N11/Drivers!N10 | O15: =Drivers!O11/Drivers!O10 | P15: =Drivers!P11/Drivers!P10 | ... R15: =Drivers!R11/Drivers!R10
A16: Free cash flow (CFO less capex) | B16: USD m | C16: =Drivers!C18-Drivers!C10 | D16: =Drivers!D18-Drivers!D10 | E16: =Drivers!E18-Drivers!E10 | F16: =Drivers!F18-Drivers!F10 | G16: =Drivers!G18-Drivers!G10 | H16: =Drivers!H18-Drivers!H10 | I16: =Drivers!I18-Drivers!I10 | J16: =Drivers!J18-Drivers!J10 | ... R16: =Drivers!R18-Drivers!R10
A17: Net debt (negative is net cash) | B17: USD m | C17: =Drivers!C20-Drivers!C23 | D17: =Drivers!D20-Drivers!D23 | E17: =Drivers!E20-Drivers!E23 | F17: =Drivers!F20-Drivers!F23 | G17: =Drivers!G20-Drivers!G23 | H17: =Drivers!H20-Drivers!H23 | I17: =Drivers!I20-Drivers!I23 | J17: =Drivers!J20-Drivers!J23 | ... R17: =Drivers!R20-Drivers!R23
A18: Net debt / annualised adjusted EBITDA | B18: x | C18: =C17/(Drivers!C9*4) | D18: =D17/(Drivers!D9*4) | E18: =E17/(Drivers!E9*4) | F18: =F17/(Drivers!F9*4) | G18: =G17/(Drivers!G9*4) | H18: =H17/(Drivers!H9*4) | I18: =I17/(Drivers!I9*4) | J18: =J17/(Drivers!J9*4) | ... R18: =R17/(Drivers!R9*4)
A19: External funding required, cumulative over estimate quarters | B19: USD m | C19: 0 | D19: =C19+Drivers!D22 | E19: =D19+Drivers!E22 | F19: =E19+Drivers!F22 | G19: =F19+Drivers!G22 | H19: =G19+Drivers!H22 | I19: =H19+Drivers!I22 | J19: =I19+Drivers!J22 | K19: =J19+Drivers!K22 | ... R19: =Q19+Drivers!R22

Sheet Disclosed
A1: period | B1: kpi | C1: value | D1: unit | E1: qualifier | F1: form | G1: filed | H1: accession | I1: page | J1: url
A2: 2025Q4 | B2: active_power_mw | C2: 170 | D2: MW | E2: approximately | F2: 6-K EX-99.2 | G2: 2026-02-12 | H2: 0001104659-26-013946 | J2: https://www.sec.gov/Archives/edgar/data/1513845/000110465926013946/tm266173d1_ex99-2.htm
A3: 2025Q3 | B3: active_power_target_ye2025_mw | C3: 100 | D3: MW | E3: target | F3: 6-K EX-99.2 | G3: 2025-11-12 | H3: 0001104659-25-109806 | J3: https://www.sec.gov/Archives/edgar/data/1513845/000110465925109806/tm2530882d1_ex99-2.htm
A4: 2025Q1 | B4: adjusted_ebitda_usd_m | C4: -62.6 | D4: USD m | F4: 6-K EX-99.1 | G4: 2025-05-20 | H4: 0001104659-25-050975 | J4: https://www.sec.gov/Archives/edgar/data/1513845/000110465925050975/tm2515580d1_ex99-1.htm
A5: 2025Q2 | B5: adjusted_ebitda_usd_m | C5: -21 | D5: USD m | F5: 6-K EX-99.1 | G5: 2025-08-07 | H5: 0001104659-25-075028 | J5: https://www.sec.gov/Archives/edgar/data/1513845/000110465925075028/tm2522866d1_ex99-1.htm
A6: 2025Q3 | B6: adjusted_ebitda_usd_m | C6: -5.2 | D6: USD m | F6: 6-K EX-99.1 | G6: 2025-11-12 | H6: 0001104659-25-109806 | J6: https://www.sec.gov/Archives/edgar/data/1513845/000110465925109806/tm2530882d1_ex99-1.htm
A7: 2025Q4 | B7: adjusted_ebitda_usd_m | C7: 15 | D7: USD m | F7: 6-K EX-99.1 | G7: 2026-02-12 | H7: 0001104659-26-013946 | J7: https://www.sec.gov/Archives/edgar/data/1513845/000110465926013946/tm266173d1_ex99-1.htm
A8: 2026Q1 | B8: adjusted_ebitda_usd_m | C8: 129.5 | D8: USD m | F8: 6-K EX-99.1 | G8: 2026-05-13 | H8: 0001104659-26-059872 | J8: https://www.sec.gov/Archives/edgar/data/1513845/000110465926059872/tm2614392d1_ex99-1.htm
A9: 2026Q2 | B9: adjusted_ebitda_usd_m | C9: 236.2 | D9: USD m | F9: 6-K EX-99.1 | G9: 2026-08-12 | H9: 0001104659-26-094568 | J9: https://www.sec.gov/Archives/edgar/data/1513845/000110465926094568/tm2622968d1_ex99-1.htm
A10: 2025Q4 | B10: ai_cloud_revenue_usd_m | C10: 214.2 | D10: USD m | F10: 6-K EX-99.2 | G10: 2026-02-12 | H10: 0001104659-26-013946 | J10: https://www.sec.gov/Archives/edgar/data/1513845/000110465926013946/tm266173d1_ex99-2.htm
A11: 2026Q1 | B11: ai_cloud_revenue_usd_m | C11: 389.7 | D11: USD m | F11: 6-K EX-99.2 | G11: 2026-05-13 | H11: 0001104659-26-059872 | J11: https://www.sec.gov/Archives/edgar/data/1513845/000110465926059872/tm2614392d1_ex99-2.htm
A12: 2026Q2 | B12: ai_cloud_revenue_usd_m | C12: 574.9 | D12: USD m | F12: 6-K EX-99.2 | G12: 2026-08-12 | H12: 0001104659-26-094568 | J12: https://www.sec.gov/Archives/edgar/data/1513845/000110465926094568/tm2622968d1_ex99-2.htm
A13: 2025Q3 | B13: arr_guidance_ye2026_high_usd_m | C13: 9000 | D13: USD m | E13: range high | F13: 6-K EX-99.2 | G13: 2025-11-12 | H13: 0001104659-25-109806 | J13: https://www.sec.gov/Archives/edgar/data/1513845/000110465925109806/tm2530882d1_ex99-2.htm
A14: 2025Q3 | B14: arr_guidance_ye2026_low_usd_m | C14: 7000 | D14: USD m | E14: range low | F14: 6-K EX-99.2 | G14: 2025-11-12 | H14: 0001104659-25-109806 | J14: https://www.sec.gov/Archives/edgar/data/1513845/000110465925109806/tm2530882d1_ex99-2.htm
A15: 2025Q1 | B15: arr_usd_m | C15: 249 | D15: USD m | F15: 6-K EX-99.2 | G15: 2025-05-20 | H15: 0001104659-25-050975 | J15: https://www.sec.gov/Archives/edgar/data/1513845/000110465925050975/tm2515580d1_ex99-2.htm
A16: 2025Q2 | B16: arr_usd_m | C16: 430 | D16: USD m | F16: 6-K EX-99.2 | G16: 2025-08-07 | H16: 0001104659-25-075028 | J16: https://www.sec.gov/Archives/edgar/data/1513845/000110465925075028/tm2522866d1_ex99-2.htm
A17: 2025Q3 | B17: arr_usd_m | C17: 551 | D17: USD m | E17: approximately | F17: 6-K EX-99.2 | G17: 2025-11-12 | H17: 0001104659-25-109806 | J17: https://www.sec.gov/Archives/edgar/data/1513845/000110465925109806/tm2530882d1_ex99-2.htm
A18: 2025Q4 | B18: arr_usd_m | C18: 1250 | D18: USD m | F18: 6-K EX-99.2 | G18: 2026-02-12 | H18: 0001104659-26-013946 | J18: https://www.sec.gov/Archives/edgar/data/1513845/000110465926013946/tm266173d1_ex99-2.htm
A19: 2026Q1 | B19: arr_usd_m | C19: 1900 | D19: USD m | F19: 6-K EX-99.2 | G19: 2026-08-12 | H19: 0001104659-26-094568 | J19: https://www.sec.gov/Archives/edgar/data/1513845/000110465926094568/tm2622968d1_ex99-2.htm
A20: 2026Q2 | B20: arr_usd_m | C20: 3000 | D20: USD m | F20: 6-K EX-99.2 | G20: 2026-08-12 | H20: 0001104659-26-094568 | J20: https://www.sec.gov/Archives/edgar/data/1513845/000110465926094568/tm2622968d1_ex99-2.htm
A21: 2025Q1 | B21: capex_usd_m | C21: 543.9 | D21: USD m | E21: comparative | F21: 6-K EX-99.1 | G21: 2026-05-13 | H21: 0001104659-26-059872 | J21: https://www.sec.gov/Archives/edgar/data/1513845/000110465926059872/tm2614392d1_ex99-1.htm
A22: 2025Q2 | B22: capex_usd_m | C22: 510.6 | D22: USD m | F22: 6-K EX-99.1 | G22: 2025-08-07 | H22: 0001104659-25-075028 | J22: https://www.sec.gov/Archives/edgar/data/1513845/000110465925075028/tm2522866d1_ex99-1.htm
A23: 2025Q3 | B23: capex_usd_m | C23: 955.5 | D23: USD m | F23: 6-K EX-99.1 | G23: 2025-11-12 | H23: 0001104659-25-109806 | J23: https://www.sec.gov/Archives/edgar/data/1513845/000110465925109806/tm2530882d1_ex99-1.htm
A24: 2025Q4 | B24: capex_usd_m | C24: 2056 | D24: USD m | F24: 6-K EX-99.1 | G24: 2026-02-12 | H24: 0001104659-26-013946 | J24: https://www.sec.gov/Archives/edgar/data/1513845/000110465926013946/tm266173d1_ex99-1.htm
A25: 2026Q1 | B25: capex_usd_m | C25: 2472.9 | D25: USD m | F25: 6-K EX-99.1 | G25: 2026-05-13 | H25: 0001104659-26-059872 | J25: https://www.sec.gov/Archives/edgar/data/1513845/000110465926059872/tm2614392d1_ex99-1.htm
A26: 2026Q2 | B26: capex_usd_m | C26: 5657.4 | D26: USD m | F26: 6-K EX-99.1 | G26: 2026-08-12 | H26: 0001104659-26-094568 | J26: https://www.sec.gov/Archives/edgar/data/1513845/000110465926094568/tm2622968d1_ex99-1.htm
A27: 2024Q4 | B27: cash_usd_m | C27: 2449.6 | D27: USD m | E27: comparative | F27: 6-K EX-99.1 | G27: 2025-05-20 | H27: 0001104659-25-050975 | J27: https://www.sec.gov/Archives/edgar/data/1513845/000110465925050975/tm2515580d1_ex99-1.htm
A28: 2025Q1 | B28: cash_usd_m | C28: 1447 | D28: USD m | F28: 6-K EX-99.1 | G28: 2025-05-20 | H28: 0001104659-25-050975 | J28: https://www.sec.gov/Archives/edgar/data/1513845/000110465925050975/tm2515580d1_ex99-1.htm
A29: 2025Q2 | B29: cash_usd_m | C29: 1679.3 | D29: USD m | F29: 6-K EX-99.1 | G29: 2025-08-07 | H29: 0001104659-25-075028 | J29: https://www.sec.gov/Archives/edgar/data/1513845/000110465925075028/tm2522866d1_ex99-1.htm
A30: 2025Q3 | B30: cash_usd_m | C30: 4794.8 | D30: USD m | F30: 6-K EX-99.1 | G30: 2025-11-12 | H30: 0001104659-25-109806 | J30: https://www.sec.gov/Archives/edgar/data/1513845/000110465925109806/tm2530882d1_ex99-1.htm
A31: 2025Q4 | B31: cash_usd_m | C31: 3678.1 | D31: USD m | F31: 6-K EX-99.1 | G31: 2026-02-12 | H31: 0001104659-26-013946 | J31: https://www.sec.gov/Archives/edgar/data/1513845/000110465926013946/tm266173d1_ex99-1.htm
A32: 2026Q1 | B32: cash_usd_m | C32: 9298.2 | D32: USD m | F32: 6-K EX-99.1 | G32: 2026-05-13 | H32: 0001104659-26-059872 | J32: https://www.sec.gov/Archives/edgar/data/1513845/000110465926059872/tm2614392d1_ex99-1.htm
A33: 2026Q2 | B33: cash_usd_m | C33: 8042.1 | D33: USD m | F33: 6-K EX-99.1 | G33: 2026-08-12 | H33: 0001104659-26-094568 | J33: https://www.sec.gov/Archives/edgar/data/1513845/000110465926094568/tm2622968d1_ex99-1.htm
A34: 2025Q2 | B34: connected_power_target_ye2025_mw | C34: 220 | D34: MW | E34: target | F34: 6-K EX-99.2 | G34: 2025-08-07 | H34: 0001104659-25-075028 | J34: https://www.sec.gov/Archives/edgar/data/1513845/000110465925075028/tm2522866d1_ex99-2.htm
A35: 2025Q3 | B35: connected_power_target_ye2026_mw | C35: 1000 | D35: MW | E35: range high | F35: 6-K EX-99.2 | G35: 2025-11-12 | H35: 0001104659-25-109806 | J35: https://www.sec.gov/Archives/edgar/data/1513845/000110465925109806/tm2530882d1_ex99-2.htm
A36: 2026Q1 | B36: connected_power_target_ye2026_mw | C36: 1000 | D36: MW | E36: range high | F36: 6-K EX-99.2 | G36: 2026-05-13 | H36: 0001104659-26-059872 | J36: https://www.sec.gov/Archives/edgar/data/1513845/000110465926059872/tm2614392d1_ex99-2.htm
A37: 2025Q4 | B37: contracted_power_gw | C37: 2 | D37: GW | E37: more than | F37: 6-K EX-99.2 | G37: 2026-02-12 | H37: 0001104659-26-013946 | J37: https://www.sec.gov/Archives/edgar/data/1513845/000110465926013946/tm266173d1_ex99-2.htm
A38: 2026Q1 | B38: contracted_power_gw | C38: 3.5 | D38: GW | E38: more than | F38: 6-K EX-99.2 | G38: 2026-05-13 | H38: 0001104659-26-059872 | J38: https://www.sec.gov/Archives/edgar/data/1513845/000110465926059872/tm2614392d1_ex99-2.htm
A39: 2025Q2 | B39: contracted_power_target_ye2026_gw | C39: 1 | D39: GW | E39: target | F39: 6-K EX-99.2 | G39: 2025-08-07 | H39: 0001104659-25-075028 | J39: https://www.sec.gov/Archives/edgar/data/1513845/000110465925075028/tm2522866d1_ex99-2.htm
A40: 2025Q3 | B40: contracted_power_target_ye2026_gw | C40: 2.5 | D40: GW | E40: more than | F40: 6-K EX-99.2 | G40: 2025-11-12 | H40: 0001104659-25-109806 | J40: https://www.sec.gov/Archives/edgar/data/1513845/000110465925109806/tm2530882d1_ex99-2.htm
...

Sheet Reported
A1: concept | B1: tag | C1: taxonomy | D1: unit | E1: start | F1: end | G1: val | H1: fy | I1: fp | J1: form | K1: filed | L1: accn | M1: frame
A2: capex | B2: PaymentsToAcquirePropertyPlantAndEquipment | C2: us-gaap | D2: USD | E2: 2011-01-01 | F2: 2011-12-31 | G2: 172900000 | H2: 2011 | I2: FY | J2: 20-F | K2: 2012-03-02 | L2: 0001047469-12-002052 | M2: CY2011
A3: capex | B3: PaymentsToAcquirePropertyPlantAndEquipment | C3: us-gaap | D3: USD | E3: 2012-01-01 | F3: 2012-12-31 | G3: 131200000 | H3: 2012 | I3: FY | J3: 20-F | K3: 2013-04-09 | L3: 0001047469-13-004131 | M3: CY2012
A4: capex | B4: PaymentsToAcquirePropertyPlantAndEquipment | C4: us-gaap | D4: USD | E4: 2013-01-01 | F4: 2013-12-31 | G4: 150800000 | H4: 2013 | I4: FY | J4: 20-F | K4: 2014-04-04 | L4: 0001047469-14-003438 | M4: CY2013
A5: capex | B5: PaymentsToAcquirePropertyPlantAndEquipment | C5: us-gaap | D5: USD | E5: 2014-01-01 | F5: 2014-12-31 | G5: 172000000 | H5: 2014 | I5: FY | J5: 20-F | K5: 2015-04-30 | L5: 0001047469-15-004230 | M5: CY2014
A6: capex | B6: PaymentsToAcquirePropertyPlantAndEquipment | C6: us-gaap | D6: USD | E6: 2015-01-01 | F6: 2015-12-31 | G6: 179000000 | H6: 2015 | I6: FY | J6: 20-F | K6: 2016-03-22 | L6: 0001047469-16-011404 | M6: CY2015
A7: capex | B7: PaymentsToAcquirePropertyPlantAndEquipment | C7: us-gaap | D7: USD | E7: 2016-01-01 | F7: 2016-12-31 | G7: 158700000 | H7: 2016 | I7: FY | J7: 20-F | K7: 2017-03-22 | L7: 0001513845-17-000004 | M7: CY2016
A8: capex | B8: PaymentsToAcquirePropertyPlantAndEquipment | C8: us-gaap | D8: USD | E8: 2017-01-01 | F8: 2017-12-31 | G8: 215100000 | H8: 2017 | I8: FY | J8: 20-F | K8: 2018-03-27 | L8: 0001513845-18-000013 | M8: CY2017
A9: capex | B9: PaymentsToAcquirePropertyPlantAndEquipment | C9: us-gaap | D9: USD | E9: 2018-01-01 | F9: 2018-12-31 | G9: 407700000 | H9: 2018 | I9: FY | J9: 20-F | K9: 2019-04-19 | L9: 0001513845-19-000009 | M9: CY2018
A10: capex | B10: PaymentsToAcquirePropertyPlantAndEquipment | C10: us-gaap | D10: USD | E10: 2019-01-01 | F10: 2019-12-31 | G10: 260500000 | H10: 2019 | I10: FY | J10: 20-F/A | K10: 2020-04-02 | L10: 0001558370-20-003563 | M10: CY2019
A11: capex | B11: PaymentsToAcquirePropertyPlantAndEquipment | C11: us-gaap | D11: USD | E11: 2020-01-01 | F11: 2020-12-31 | G11: 332300000 | H11: 2020 | I11: FY | J11: 20-F | K11: 2021-04-01 | L11: 0001513845-21-000014 | M11: CY2020
A12: capex | B12: PaymentsToAcquirePropertyPlantAndEquipment | C12: us-gaap | D12: USD | E12: 2021-01-01 | F12: 2021-12-31 | G12: 600600000 | H12: 2021 | I12: FY | J12: 20-F | K12: 2022-04-20 | L12: 0001558370-22-005654 | M12: CY2021
A13: capex | B13: PaymentsToAcquirePropertyPlantAndEquipment | C13: us-gaap | D13: USD | E13: 2022-01-01 | F13: 2022-12-31 | G13: 718600000 | H13: 2022 | I13: FY | J13: 20-F | K13: 2023-04-20 | L13: 0001558370-23-006319
A14: capex | B14: PaymentsToAcquirePropertyPlantAndEquipment | C14: us-gaap | D14: USD | E14: 2022-01-01 | F14: 2022-12-31 | G14: 14600000 | H14: 2024 | I14: FY | J14: 20-F | K14: 2025-04-30 | L14: 0001558370-25-005991 | M14: CY2022
A15: capex | B15: PaymentsToAcquirePropertyPlantAndEquipment | C15: us-gaap | D15: USD | E15: 2023-01-01 | F15: 2023-12-31 | G15: 1010600000 | H15: 2023 | I15: FY | J15: 20-F | K15: 2024-04-26 | L15: 0001558370-24-005891
A16: capex | B16: PaymentsToAcquirePropertyPlantAndEquipment | C16: us-gaap | D16: USD | E16: 2023-01-01 | F16: 2023-12-31 | G16: 83400000 | H16: 2024 | I16: FY | J16: 20-F | K16: 2025-04-30 | L16: 0001558370-25-005991
A17: capex | B17: PaymentsToAcquirePropertyPlantAndEquipment | C17: us-gaap | D17: USD | E17: 2023-01-01 | F17: 2023-12-31 | G17: 82900000 | H17: 2025 | I17: FY | J17: 20-F | K17: 2026-04-30 | L17: 0001104659-26-052948 | M17: CY2023
A18: capex | B18: PaymentsToAcquirePropertyPlantAndEquipment | C18: us-gaap | D18: USD | E18: 2024-01-01 | F18: 2024-12-31 | G18: 807700000 | H18: 2024 | I18: FY | J18: 20-F | K18: 2025-04-30 | L18: 0001558370-25-005991
A19: capex | B19: PaymentsToAcquirePropertyPlantAndEquipment | C19: us-gaap | D19: USD | E19: 2024-01-01 | F19: 2024-12-31 | G19: 807500000 | H19: 2025 | I19: FY | J19: 20-F | K19: 2026-04-30 | L19: 0001104659-26-052948 | M19: CY2024
A20: capex | B20: PaymentsToAcquirePropertyPlantAndEquipment | C20: us-gaap | D20: USD | E20: 2025-01-01 | F20: 2025-12-31 | G20: 4066000000 | H20: 2025 | I20: FY | J20: 20-F | K20: 2026-04-30 | L20: 0001104659-26-052948 | M20: CY2025
A21: cash | B21: CashAndCashEquivalentsAtCarryingValue | C21: us-gaap | D21: USD | F21: 2010-12-31 | G21: 104700000 | H21: 2011 | I21: FY | J21: 20-F | K21: 2012-03-02 | L21: 0001047469-12-002052 | M21: CY2010Q4I
A22: cash | B22: CashAndCashEquivalentsAtCarryingValue | C22: us-gaap | D22: USD | F22: 2011-12-31 | G22: 196400000 | H22: 2011 | I22: FY | J22: 20-F | K22: 2012-03-02 | L22: 0001047469-12-002052
A23: cash | B23: CashAndCashEquivalentsAtCarryingValue | C23: us-gaap | D23: USD | F23: 2011-12-31 | G23: 195200000 | H23: 2012 | I23: FY | J23: 20-F | K23: 2013-04-09 | L23: 0001047469-13-004131 | M23: CY2011Q4I
A24: cash | B24: CashAndCashEquivalentsAtCarryingValue | C24: us-gaap | D24: USD | F24: 2012-12-31 | G24: 244500000 | H24: 2012 | I24: FY | J24: 20-F | K24: 2013-04-09 | L24: 0001047469-13-004131
A25: cash | B25: CashAndCashEquivalentsAtCarryingValue | C25: us-gaap | D25: USD | F25: 2012-12-31 | G25: 226900000 | H25: 2013 | I25: FY | J25: 20-F | K25: 2014-04-04 | L25: 0001047469-14-003438 | M25: CY2012Q4I
A26: cash | B26: CashAndCashEquivalentsAtCarryingValue | C26: us-gaap | D26: USD | F26: 2013-12-31 | G26: 1020300000 | H26: 2013 | I26: FY | J26: 20-F | K26: 2014-04-04 | L26: 0001047469-14-003438
A27: cash | B27: CashAndCashEquivalentsAtCarryingValue | C27: us-gaap | D27: USD | F27: 2013-12-31 | G27: 593600000 | H27: 2014 | I27: FY | J27: 20-F | K27: 2015-04-30 | L27: 0001047469-15-004230 | M27: CY2013Q4I
A28: cash | B28: CashAndCashEquivalentsAtCarryingValue | C28: us-gaap | D28: USD | F28: 2014-12-31 | G28: 313600000 | H28: 2014 | I28: FY | J28: 20-F | K28: 2015-04-30 | L28: 0001047469-15-004230
A29: cash | B29: CashAndCashEquivalentsAtCarryingValue | C29: us-gaap | D29: USD | F29: 2014-12-31 | G29: 242100000 | H29: 2015 | I29: FY | J29: 20-F | K29: 2016-03-22 | L29: 0001047469-16-011404 | M29: CY2014Q4I
A30: cash | B30: CashAndCashEquivalentsAtCarryingValue | C30: us-gaap | D30: USD | F30: 2015-12-31 | G30: 332600000 | H30: 2015 | I30: FY | J30: 20-F | K30: 2016-03-22 | L30: 0001047469-16-011404
A31: cash | B31: CashAndCashEquivalentsAtCarryingValue | C31: us-gaap | D31: USD | F31: 2015-12-31 | G31: 399600000 | H31: 2016 | I31: FY | J31: 20-F | K31: 2017-03-22 | L31: 0001513845-17-000004 | M31: CY2015Q4I
A32: cash | B32: CashAndCashEquivalentsAtCarryingValue | C32: us-gaap | D32: USD | F32: 2016-12-31 | G32: 465400000 | H32: 2016 | I32: FY | J32: 20-F | K32: 2017-03-22 | L32: 0001513845-17-000004
A33: cash | B33: CashAndCashEquivalentsAtCarryingValue | C33: us-gaap | D33: USD | F33: 2016-12-31 | G33: 490100000 | H33: 2017 | I33: FY | J33: 20-F | K33: 2018-03-27 | L33: 0001513845-18-000013 | M33: CY2016Q4I
A34: cash | B34: CashAndCashEquivalentsAtCarryingValue | C34: us-gaap | D34: USD | F34: 2017-12-31 | G34: 740700000 | H34: 2017 | I34: FY | J34: 20-F | K34: 2018-03-27 | L34: 0001513845-18-000013
A35: cash | B35: CashAndCashEquivalentsAtCarryingValue | C35: us-gaap | D35: USD | F35: 2017-12-31 | G35: 614100000 | H35: 2018 | I35: FY | J35: 20-F | K35: 2019-04-19 | L35: 0001513845-19-000009 | M35: CY2017Q4I
A36: cash | B36: CashAndCashEquivalentsAtCarryingValue | C36: us-gaap | D36: USD | F36: 2018-12-31 | G36: 990300000 | H36: 2018 | I36: FY | J36: 20-F | K36: 2019-04-19 | L36: 0001513845-19-000009
A37: cash | B37: CashAndCashEquivalentsAtCarryingValue | C37: us-gaap | D37: USD | F37: 2018-12-31 | G37: 872500000 | H37: 2019 | I37: FY | J37: 20-F/A | K37: 2020-04-02 | L37: 0001558370-20-003563 | M37: CY2018Q4I
A38: cash | B38: CashAndCashEquivalentsAtCarryingValue | C38: us-gaap | D38: USD | F38: 2019-12-31 | G38: 715500000 | H38: 2019 | I38: FY | J38: 20-F/A | K38: 2020-04-02 | L38: 0001558370-20-003563
A39: cash | B39: CashAndCashEquivalentsAtCarryingValue | C39: us-gaap | D39: USD | F39: 2019-12-31 | G39: 763600000 | H39: 2020 | I39: FY | J39: 20-F | K39: 2021-04-01 | L39: 0001513845-21-000014 | M39: CY2019Q4I
A40: cash | B40: CashAndCashEquivalentsAtCarryingValue | C40: us-gaap | D40: USD | F40: 2020-12-31 | G40: 1792200000 | H40: 2020 | I40: FY | J40: 20-F | K40: 2021-04-01 | L40: 0001513845-21-000014
...

Sheet Sensitivities
A1: index | B1: value | C1: arr_end_2026_usd_m | D1: external_funding_usd_m | E1: minimum_cash_usd_m | F1: net_debt_to_ebitda_end | G1: payback_net_of_prepayment_end | H1: revenue_final_year_usd_bn
A2: base case | C2: 8600 | D2: 0 | E2: 2331.4059 | F2: 1.9345734 | G2: 2.5290916 | H2: 24.881633
A3: active_power_mw_2026q2 = 250 | B3: 250 | C3: 8600 | D3: 0 | E3: 2331.4059 | F3: 1.9345734 | G3: 2.4716122 | H3: 24.881633
A4: active_power_mw_2026q2 = 400 | B4: 400 | C4: 8600 | D4: 0 | E4: 2331.4059 | F4: 1.9345734 | G4: 2.6440503 | H4: 24.881633
A5: mw_added_per_quarter = 150 | B5: 150 | C5: 8600 | D5: 0 | E5: 3550.376 | F5: 1.8525265 | G5: 2.5503365 | H5: 20.767347
A6: mw_added_per_quarter = 300 | B6: 300 | C6: 8600 | D6: 2224.9397 | E6: 2000 | F6: 1.9083481 | G6: 2.5032904 | H6: 33.110204
A7: arr_per_new_mw_year_usd_m = 10 | B7: 10 | C7: 7000 | D7: 3038.9701 | E7: 2000 | F7: 2.737246 | G7: 3.4027778 | H7: 18.612245
A8: arr_per_new_mw_year_usd_m = 22 | B8: 22 | C8: 11800 | D8: 0 | E8: 4714.4684 | F8: 0.83846812 | G8: 1.6710069 | H8: 37.420408
A9: revenue_to_midpoint_arr = 0.9 | B9: 0.9 | C9: 8600 | D9: 348.90427 | E9: 2000 | F9: 2.1295609 | G9: 2.6976977 | H9: 23.326531
A10: revenue_to_midpoint_arr = 1 | B10: 1 | C10: 8600 | D10: 0 | E10: 2733.1916 | F10: 1.8004675 | G10: 2.4279279 | H10: 25.918367
A11: ai_cloud_share_of_revenue = 0.95 | B11: 0.95 | C11: 8600 | D11: 0 | E11: 2635.9171 | F11: 1.8319413 | G11: 2.4516704 | H11: 25.667368
A12: ai_cloud_share_of_revenue = 1 | B12: 1 | C12: 8600 | D12: 0 | E12: 2138.5487 | F12: 2.0029948 | G12: 2.5807057 | H12: 24.384
A13: adjusted_ebitda_margin = 0.35 | B13: 0.35 | C13: 8600 | D13: 2808.766 | E13: 2000 | F13: 2.6157081 | G13: 3.2516892 | H13: 24.881633
A14: adjusted_ebitda_margin = 0.55 | B14: 0.55 | C14: 8600 | D14: 0 | E14: 4017.436 | F14: 1.3250011 | G14: 2.0692568 | H14: 24.881633
... A32: mw_added_2026q4 = 500 | B32: 500 | C32: 10700 | D32: 0 | E32: 2028.4129 | F32: 1.8999653 | G32: 2.522564 | H32: 26.938776
